2022-04-10 14:34:32,358 ERROR: Exception on /Graph1 [GET] [in /home/dh_5ejt8t/dev.project.runningdigitally.com/venv2/lib/python3.8/site-packages/flask/app.py:1455]
Traceback (most recent call last):
  File "/home/dh_5ejt8t/dev.project.runningdigitally.com/venv2/lib/python3.8/site-packages/flask/app.py", line 2077, in wsgi_app
    response = self.full_dispatch_request()
  File "/home/dh_5ejt8t/dev.project.runningdigitally.com/venv2/lib/python3.8/site-packages/flask/app.py", line 1525, in full_dispatch_request
    rv = self.handle_user_exception(e)
  File "/home/dh_5ejt8t/dev.project.runningdigitally.com/venv2/lib/python3.8/site-packages/flask/app.py", line 1523, in full_dispatch_request
    rv = self.dispatch_request()
  File "/home/dh_5ejt8t/dev.project.runningdigitally.com/venv2/lib/python3.8/site-packages/flask/app.py", line 1509, in dispatch_request
    return self.ensure_sync(self.view_functions[rule.endpoint])(**req.view_args)
  File "/home/dh_5ejt8t/dev.project.runningdigitally.com/app/routes.py", line 43, in graph1
    return render_template('graph.html', graphJSON=graphJSON, title='Graph')
  File "/home/dh_5ejt8t/dev.project.runningdigitally.com/venv2/lib/python3.8/site-packages/flask/templating.py", line 149, in render_template
    ctx.app.jinja_env.get_or_select_template(template_name_or_list),
  File "/home/dh_5ejt8t/dev.project.runningdigitally.com/venv2/lib/python3.8/site-packages/jinja2/environment.py", line 1071, in get_or_select_template
    return self.get_template(template_name_or_list, parent, globals)
  File "/home/dh_5ejt8t/dev.project.runningdigitally.com/venv2/lib/python3.8/site-packages/jinja2/environment.py", line 1000, in get_template
    return self._load_template(name, globals)
  File "/home/dh_5ejt8t/dev.project.runningdigitally.com/venv2/lib/python3.8/site-packages/jinja2/environment.py", line 959, in _load_template
    template = self.loader.load(self, name, self.make_globals(globals))
  File "/home/dh_5ejt8t/dev.project.runningdigitally.com/venv2/lib/python3.8/site-packages/jinja2/loaders.py", line 126, in load
    source, filename, uptodate = self.get_source(environment, name)
  File "/home/dh_5ejt8t/dev.project.runningdigitally.com/venv2/lib/python3.8/site-packages/flask/templating.py", line 59, in get_source
    return self._get_source_fast(environment, template)
  File "/home/dh_5ejt8t/dev.project.runningdigitally.com/venv2/lib/python3.8/site-packages/flask/templating.py", line 95, in _get_source_fast
    raise TemplateNotFound(template)
jinja2.exceptions.TemplateNotFound: graph.html
2022-04-10 14:34:44,444 ERROR: Exception on / [GET] [in /home/dh_5ejt8t/dev.project.runningdigitally.com/venv2/lib/python3.8/site-packages/flask/app.py:1455]
Traceback (most recent call last):
  File "/home/dh_5ejt8t/dev.project.runningdigitally.com/venv2/lib/python3.8/site-packages/flask/app.py", line 2077, in wsgi_app
    response = self.full_dispatch_request()
  File "/home/dh_5ejt8t/dev.project.runningdigitally.com/venv2/lib/python3.8/site-packages/flask/app.py", line 1525, in full_dispatch_request
    rv = self.handle_user_exception(e)
  File "/home/dh_5ejt8t/dev.project.runningdigitally.com/venv2/lib/python3.8/site-packages/flask/app.py", line 1523, in full_dispatch_request
    rv = self.dispatch_request()
  File "/home/dh_5ejt8t/dev.project.runningdigitally.com/venv2/lib/python3.8/site-packages/flask/app.py", line 1509, in dispatch_request
    return self.ensure_sync(self.view_functions[rule.endpoint])(**req.view_args)
  File "/home/dh_5ejt8t/dev.project.runningdigitally.com/app/routes.py", line 31, in index
    return render_template('index.html', title='Home')
  File "/home/dh_5ejt8t/dev.project.runningdigitally.com/venv2/lib/python3.8/site-packages/flask/templating.py", line 148, in render_template
    return _render(
  File "/home/dh_5ejt8t/dev.project.runningdigitally.com/venv2/lib/python3.8/site-packages/flask/templating.py", line 128, in _render
    rv = template.render(context)
  File "/home/dh_5ejt8t/dev.project.runningdigitally.com/venv2/lib/python3.8/site-packages/jinja2/environment.py", line 1291, in render
    self.environment.handle_exception()
  File "/home/dh_5ejt8t/dev.project.runningdigitally.com/venv2/lib/python3.8/site-packages/jinja2/environment.py", line 926, in handle_exception
    raise rewrite_traceback_stack(source=source)
  File "/home/dh_5ejt8t/dev.project.runningdigitally.com/app/templates/index.html", line 1, in top-level template code
    {% extends "base2.html" %}
  File "/home/dh_5ejt8t/dev.project.runningdigitally.com/app/templates/base2.html", line 1, in top-level template code
    {% extends 'bootstrap/base.html' %}
  File "/home/dh_5ejt8t/dev.project.runningdigitally.com/venv2/lib/python3.8/site-packages/flask_bootstrap/templates/bootstrap/base.html", line 1, in top-level template code
    {% block doc -%}
  File "/home/dh_5ejt8t/dev.project.runningdigitally.com/venv2/lib/python3.8/site-packages/flask_bootstrap/templates/bootstrap/base.html", line 4, in block 'doc'
    {%- block html %}
  File "/home/dh_5ejt8t/dev.project.runningdigitally.com/venv2/lib/python3.8/site-packages/flask_bootstrap/templates/bootstrap/base.html", line 20, in block 'html'
    {% block body -%}
  File "/home/dh_5ejt8t/dev.project.runningdigitally.com/venv2/lib/python3.8/site-packages/flask_bootstrap/templates/bootstrap/base.html", line 23, in block 'body'
    {% block content -%}
  File "/home/dh_5ejt8t/dev.project.runningdigitally.com/app/templates/index.html", line 8, in block 'content'
    <h3> Meanwhile, you can check out our "fictitious" City-Fruit <a href="{{ url_for('graph') }}">Graph</a> we put together for you </h3>
  File "/home/dh_5ejt8t/dev.project.runningdigitally.com/venv2/lib/python3.8/site-packages/flask/helpers.py", line 336, in url_for
    return appctx.app.handle_url_build_error(error, endpoint, values)
  File "/home/dh_5ejt8t/dev.project.runningdigitally.com/venv2/lib/python3.8/site-packages/flask/helpers.py", line 323, in url_for
    rv = url_adapter.build(
  File "/home/dh_5ejt8t/dev.project.runningdigitally.com/venv2/lib/python3.8/site-packages/werkzeug/routing.py", line 2307, in build
    raise BuildError(endpoint, values, method, self)
werkzeug.routing.BuildError: Could not build url for endpoint 'graph'. Did you mean 'graph1' instead?
2022-04-10 14:34:48,444 ERROR: Exception on / [GET] [in /home/dh_5ejt8t/dev.project.runningdigitally.com/venv2/lib/python3.8/site-packages/flask/app.py:1455]
Traceback (most recent call last):
  File "/home/dh_5ejt8t/dev.project.runningdigitally.com/venv2/lib/python3.8/site-packages/flask/app.py", line 2077, in wsgi_app
    response = self.full_dispatch_request()
  File "/home/dh_5ejt8t/dev.project.runningdigitally.com/venv2/lib/python3.8/site-packages/flask/app.py", line 1525, in full_dispatch_request
    rv = self.handle_user_exception(e)
  File "/home/dh_5ejt8t/dev.project.runningdigitally.com/venv2/lib/python3.8/site-packages/flask/app.py", line 1523, in full_dispatch_request
    rv = self.dispatch_request()
  File "/home/dh_5ejt8t/dev.project.runningdigitally.com/venv2/lib/python3.8/site-packages/flask/app.py", line 1509, in dispatch_request
    return self.ensure_sync(self.view_functions[rule.endpoint])(**req.view_args)
  File "/home/dh_5ejt8t/dev.project.runningdigitally.com/app/routes.py", line 31, in index
    return render_template('index.html', title='Home')
  File "/home/dh_5ejt8t/dev.project.runningdigitally.com/venv2/lib/python3.8/site-packages/flask/templating.py", line 148, in render_template
    return _render(
  File "/home/dh_5ejt8t/dev.project.runningdigitally.com/venv2/lib/python3.8/site-packages/flask/templating.py", line 128, in _render
    rv = template.render(context)
  File "/home/dh_5ejt8t/dev.project.runningdigitally.com/venv2/lib/python3.8/site-packages/jinja2/environment.py", line 1291, in render
    self.environment.handle_exception()
  File "/home/dh_5ejt8t/dev.project.runningdigitally.com/venv2/lib/python3.8/site-packages/jinja2/environment.py", line 926, in handle_exception
    raise rewrite_traceback_stack(source=source)
  File "/home/dh_5ejt8t/dev.project.runningdigitally.com/app/templates/index.html", line 1, in top-level template code
    {% extends "base2.html" %}
  File "/home/dh_5ejt8t/dev.project.runningdigitally.com/app/templates/base2.html", line 1, in top-level template code
    {% extends 'bootstrap/base.html' %}
  File "/home/dh_5ejt8t/dev.project.runningdigitally.com/venv2/lib/python3.8/site-packages/flask_bootstrap/templates/bootstrap/base.html", line 1, in top-level template code
    {% block doc -%}
  File "/home/dh_5ejt8t/dev.project.runningdigitally.com/venv2/lib/python3.8/site-packages/flask_bootstrap/templates/bootstrap/base.html", line 4, in block 'doc'
    {%- block html %}
  File "/home/dh_5ejt8t/dev.project.runningdigitally.com/venv2/lib/python3.8/site-packages/flask_bootstrap/templates/bootstrap/base.html", line 20, in block 'html'
    {% block body -%}
  File "/home/dh_5ejt8t/dev.project.runningdigitally.com/venv2/lib/python3.8/site-packages/flask_bootstrap/templates/bootstrap/base.html", line 23, in block 'body'
    {% block content -%}
  File "/home/dh_5ejt8t/dev.project.runningdigitally.com/app/templates/index.html", line 8, in block 'content'
    <h3> Meanwhile, you can check out our "fictitious" City-Fruit <a href="{{ url_for('graph') }}">Graph</a> we put together for you </h3>
  File "/home/dh_5ejt8t/dev.project.runningdigitally.com/venv2/lib/python3.8/site-packages/flask/helpers.py", line 336, in url_for
    return appctx.app.handle_url_build_error(error, endpoint, values)
  File "/home/dh_5ejt8t/dev.project.runningdigitally.com/venv2/lib/python3.8/site-packages/flask/helpers.py", line 323, in url_for
    rv = url_adapter.build(
  File "/home/dh_5ejt8t/dev.project.runningdigitally.com/venv2/lib/python3.8/site-packages/werkzeug/routing.py", line 2307, in build
    raise BuildError(endpoint, values, method, self)
werkzeug.routing.BuildError: Could not build url for endpoint 'graph'. Did you mean 'graph1' instead?
2022-04-10 14:36:32,518 INFO: App startup [in /home/dh_5ejt8t/dev.project.runningdigitally.com/app/__init__.py:59]
